Workbook

Sheet CONSOLIDADO - ALCANCE 
C1: Contacto wsp : | D1: 1150000071 | I1: =IF(I4<>"","¡ ADVERTENCIA ! Por favor eliminar el mensaje escrito una vez haya recibido la respuesta.","")
M2: Celda F5
B3: Responsable: | I3: Enviar Mensaje | M3: =IF(AND(F5="",F6=""),"",N(F5)-N(F6)) -> -0.31286681
E4: Total de dias / Porcentaje | X4: Lista Ajustado | Z4: Diferencia Dias
B5: Fecha de inicio | C5: 45880 | E5: =IF(Z5="","0 Dias de "&M6,CONCATENATE(Z5," Dias de "&M6)) -> 91 Dias de 150 | F5: =IF(C5="","",Z5/M6) -> 0.60666667 | M5: Celda F5 Cantidad dias | X5: Si | Z5: =IF(C5="","",C6-C5) -> 91
B6: Fecha actual | C6: =TODAY() -> 45971 | E6: % de Avance | F6: =C13 -> 0.91953348 | M6: 150 | X6: No
B8: Rubro | C8: % avance | D8: Unid invent | E8: Unid Fisicas | F8: Dif | G8: Ajuste $$
B9: Medicamentos | C9: =Medicamentos!I155 -> 0.91851852 | D9: =SUMIF(Medicamentos!I10:I154,"Si",Medicamentos!D10:D154) -> 9714 | E9: =SUMIF(Medicamentos!I10:I154,"Si",Medicamentos!E10:E154) -> 9606 | F9: =E9-D9 -> -108 | G9: =SUMIF(Medicamentos!I10:I154,"Si",Medicamentos!F10:F154) -> -217534.39
B10: Perfumeria | C10: =Perfumería!I84 -> 1 | D10: =SUMIF(Perfumería!I10:I83,"Si",Perfumería!D10:D83) -> 8600 | E10: =SUMIF(Perfumería!I10:I83,"Si",Perfumería!E10:E83) -> 8509 | F10: =E10-D10 -> -91 | G10: =SUMIF(Perfumería!I10:I83,"Si",Perfumería!F10:F83) -> -958277.64 | I10: Respuesta Recibido
B11: Accesorios | C11: =Accesorios!I124 -> 0.99038462 | D11: =SUMIF(Accesorios!I10:I123,"Si",Accesorios!D10:D123) -> 2085 | E11: =SUMIF(Accesorios!I10:I123,"Si",Accesorios!E10:E123) -> 1930 | F11: =E11-D11 -> -155 | G11: =SUMIF(Accesorios!I10:I123,"Si",Accesorios!F10:F123) -> -189296.57 | I11: =IF([1]Avisos_Mensajes!$N$160="","",[1]Avisos_Mensajes!$N$160)
B12: Varios | C12: =Varios!I46 -> 0.76923077 | D12: =SUMIF(Varios!I10:I45,"Si",Varios!D10:D45) -> 2973 | E12: =SUMIF(Varios!I10:I45,"Si",Varios!E10:E45) -> 2464 | F12: =E12-D12 -> -509 | G12: =SUMIF(Varios!I10:I45,"Si",Varios!F10:F45) -> -1268813.1
B13: Total inventario | C13: =SUM(C9:C12)/4 -> 0.91953348 | D13: =SUM(D9:D12) -> 23372 | E13: =SUM(E9:E12) -> 22509 | F13: =SUM(F9:F12) -> -863 | G13: =SUM(G9:G12) -> -2633921.7
D15: =IF(B16="","","↓ Nuevo Aviso ↓")
B16: =IF([1]Avisos_Mensajes!$B$5="","",IF(AND([1]Avisos_Mensajes!$B$5<>"",[1]Avisos_Mensajes!$AF$1<[1]Avisos_Mensajes!$H$4),[1]Avisos_Mensajes!$B$5,""))

Sheet Medicamentos
B2: Evolución de control Categoria Medicamentos | E2: =IF('CONSOLIDADO - ALCANCE '!Z5>='CONSOLIDADO - ALCANCE '!M6,"PLANILLA FINALIZADA",IF('CONSOLIDADO - ALCANCE '!M3>0.09,CONCATENATE("Planilla Atrasada un ",TEXT('CONSOLIDADO - ALCANCE '!M3,"0%")),""))
C5: =COUNTIF(I10:I154,"Si")/B155 -> 0.91851852 | G5: =IF('CONSOLIDADO - ALCANCE '!D15<>"","Nuevo Aviso en la Primer Hoja","")
A9: Cluster | B9: Laboratorio | C9: Fecha de conteo | D9: Cajas | E9: Conteo Fisico | F9: Costo Dif | G9: Diferencias | H9: Chek | I9: Ajustado
A10: A | B10: ANDRÓMACO | C10: 45955 | D10: 222 | E10: 224 | F10: =SUMIF(Ajustes!$A$3:$A$150,Medicamentos!B10,Ajustes!$C$3:$C$150)+SUMIF(Ajustes!$A$3:$A$150,Medicamentos!B10,Ajustes!$E$3:$E$150) -> 198125.84 | G10: =E10-D10 -> 2 | H10: =IF(C10<>"",0,"") -> 0 | I10: =IF(AND(D10="0",E10="0"),"SI",IF(COUNTIF(Ajustes!$A$3:$A$150,B10),"SI",IF(AND(D10=0,E10=0,NOT(ISBLANK(D10)),NOT(ISBLANK(E10))),"SI",""))) -> SI
A11: A | B11: BAGÓ | F11: =SUMIF(Ajustes!$A$3:$A$150,Medicamentos!B11,Ajustes!$C$3:$C$150)+SUMIF(Ajustes!$A$3:$A$150,Medicamentos!B11,Ajustes!$E$3:$E$150) -> 0 | G11: =E11-D11 -> 0 | H11: =IF(C11<>"",0,"") | I11: =IF(AND(D11="0",E11="0"),"SI",IF(COUNTIF(Ajustes!$A$3:$A$150,B11),"SI",IF(AND(D11=0,E11=0,NOT(ISBLANK(D11)),NOT(ISBLANK(E11))),"SI","")))
A12: A | B12: BALIARDA | C12: 45965 | D12: 515 | E12: 526 | F12: =SUMIF(Ajustes!$A$3:$A$150,Medicamentos!B12,Ajustes!$C$3:$C$150)+SUMIF(Ajustes!$A$3:$A$150,Medicamentos!B12,Ajustes!$E$3:$E$150) -> 364422.48 | G12: =E12-D12 -> 11 | H12: =IF(C12<>"",0,"") -> 0 | I12: =IF(AND(D12="0",E12="0"),"SI",IF(COUNTIF(Ajustes!$A$3:$A$150,B12),"SI",IF(AND(D12=0,E12=0,NOT(ISBLANK(D12)),NOT(ISBLANK(E12))),"SI",""))) -> SI
A13: A | B13: BAYER CONSUMER | C13: 45959 | D13: 786 | E13: 743 | F13: =SUMIF(Ajustes!$A$3:$A$150,Medicamentos!B13,Ajustes!$C$3:$C$150)+SUMIF(Ajustes!$A$3:$A$150,Medicamentos!B13,Ajustes!$E$3:$E$150) -> -279504.79 | G13: =E13-D13 -> -43 | H13: =IF(C13<>"",0,"") -> 0 | I13: =IF(AND(D13="0",E13="0"),"SI",IF(COUNTIF(Ajustes!$A$3:$A$150,B13),"SI",IF(AND(D13=0,E13=0,NOT(ISBLANK(D13)),NOT(ISBLANK(E13))),"SI",""))) -> SI
A14: A | B14: CASASCO | C14: 45957 | D14: 742 | E14: 769 | F14: =SUMIF(Ajustes!$A$3:$A$150,Medicamentos!B14,Ajustes!$C$3:$C$150)+SUMIF(Ajustes!$A$3:$A$150,Medicamentos!B14,Ajustes!$E$3:$E$150) -> 0 | G14: =E14-D14 -> 27 | H14: =IF(C14<>"",0,"") -> 0 | I14: =IF(AND(D14="0",E14="0"),"SI",IF(COUNTIF(Ajustes!$A$3:$A$150,B14),"SI",IF(AND(D14=0,E14=0,NOT(ISBLANK(D14)),NOT(ISBLANK(E14))),"SI","")))
A15: A | B15: CASSARÁ | C15: 45888 | D15: 225 | E15: 217 | F15: =SUMIF(Ajustes!$A$3:$A$150,Medicamentos!B15,Ajustes!$C$3:$C$150)+SUMIF(Ajustes!$A$3:$A$150,Medicamentos!B15,Ajustes!$E$3:$E$150) -> -157580 | G15: =E15-D15 -> -8 | H15: =IF(C15<>"",0,"") -> 0 | I15: =IF(AND(D15="0",E15="0"),"SI",IF(COUNTIF(Ajustes!$A$3:$A$150,B15),"SI",IF(AND(D15=0,E15=0,NOT(ISBLANK(D15)),NOT(ISBLANK(E15))),"SI",""))) -> SI
A16: A | B16: ELEA | F16: =SUMIF(Ajustes!$A$3:$A$150,Medicamentos!B16,Ajustes!$C$3:$C$150)+SUMIF(Ajustes!$A$3:$A$150,Medicamentos!B16,Ajustes!$E$3:$E$150) -> 0 | G16: =E16-D16 -> 0 | H16: =IF(C16<>"",0,"") | I16: =IF(AND(D16="0",E16="0"),"SI",IF(COUNTIF(Ajustes!$A$3:$A$150,B16),"SI",IF(AND(D16=0,E16=0,NOT(ISBLANK(D16)),NOT(ISBLANK(E16))),"SI","")))
A17: A | B17: GADOR | C17: 45961 | D17: 590 | E17: 609 | F17: =SUMIF(Ajustes!$A$3:$A$150,Medicamentos!B17,Ajustes!$C$3:$C$150)+SUMIF(Ajustes!$A$3:$A$150,Medicamentos!B17,Ajustes!$E$3:$E$150) -> -131743.2 | G17: =E17-D17 -> 19 | H17: =IF(C17<>"",0,"") -> 0 | I17: =IF(AND(D17="0",E17="0"),"SI",IF(COUNTIF(Ajustes!$A$3:$A$150,B17),"SI",IF(AND(D17=0,E17=0,NOT(ISBLANK(D17)),NOT(ISBLANK(E17))),"SI",""))) -> SI
A18: A | B18: GENOMMA LAB. | F18: =SUMIF(Ajustes!$A$3:$A$150,Medicamentos!B18,Ajustes!$C$3:$C$150)+SUMIF(Ajustes!$A$3:$A$150,Medicamentos!B18,Ajustes!$E$3:$E$150) -> 0 | G18: =E18-D18 -> 0 | H18: =IF(C18<>"",0,"") | I18: =IF(AND(D18="0",E18="0"),"SI",IF(COUNTIF(Ajustes!$A$3:$A$150,B18),"SI",IF(AND(D18=0,E18=0,NOT(ISBLANK(D18)),NOT(ISBLANK(E18))),"SI","")))
A19: A | B19: GLAXOSMITHKLINE | C19: 45969 | D19: 207 | E19: 205 | F19: =SUMIF(Ajustes!$A$3:$A$150,Medicamentos!B19,Ajustes!$C$3:$C$150)+SUMIF(Ajustes!$A$3:$A$150,Medicamentos!B19,Ajustes!$E$3:$E$150) -> -27691.49 | G19: =E19-D19 -> -2 | H19: =IF(C19<>"",0,"") -> 0 | I19: =IF(AND(D19="0",E19="0"),"SI",IF(COUNTIF(Ajustes!$A$3:$A$150,B19),"SI",IF(AND(D19=0,E19=0,NOT(ISBLANK(D19)),NOT(ISBLANK(E19))),"SI",""))) -> SI
A20: A | B20: LABORATORIO GRA | F20: =SUMIF(Ajustes!$A$3:$A$150,Medicamentos!B20,Ajustes!$C$3:$C$150)+SUMIF(Ajustes!$A$3:$A$150,Medicamentos!B20,Ajustes!$E$3:$E$150) -> 0 | G20: =E20-D20 -> 0 | H20: =IF(C20<>"",0,"") | I20: =IF(AND(D20="0",E20="0"),"SI",IF(COUNTIF(Ajustes!$A$3:$A$150,B20),"SI",IF(AND(D20=0,E20=0,NOT(ISBLANK(D20)),NOT(ISBLANK(E20))),"SI","")))
A21: A | B21: LABORATORIOS BE | F21: =SUMIF(Ajustes!$A$3:$A$150,Medicamentos!B21,Ajustes!$C$3:$C$150)+SUMIF(Ajustes!$A$3:$A$150,Medicamentos!B21,Ajustes!$E$3:$E$150) -> 0 | G21: =E21-D21 -> 0 | H21: =IF(C21<>"",0,"") | I21: =IF(AND(D21="0",E21="0"),"SI",IF(COUNTIF(Ajustes!$A$3:$A$150,B21),"SI",IF(AND(D21=0,E21=0,NOT(ISBLANK(D21)),NOT(ISBLANK(E21))),"SI","")))
A22: A | B22: LAZAR | C22: 45954 | D22: 162 | E22: 157 | F22: =SUMIF(Ajustes!$A$3:$A$150,Medicamentos!B22,Ajustes!$C$3:$C$150)+SUMIF(Ajustes!$A$3:$A$150,Medicamentos!B22,Ajustes!$E$3:$E$150) -> -174134.71 | G22: =E22-D22 -> -5 | H22: =IF(C22<>"",0,"") -> 0 | I22: =IF(AND(D22="0",E22="0"),"SI",IF(COUNTIF(Ajustes!$A$3:$A$150,B22),"SI",IF(AND(D22=0,E22=0,NOT(ISBLANK(D22)),NOT(ISBLANK(E22))),"SI",""))) -> SI
A23: A | B23: LEPETIT | C23: 45885 | D23: 96 | E23: 94 | F23: =SUMIF(Ajustes!$A$3:$A$150,Medicamentos!B23,Ajustes!$C$3:$C$150)+SUMIF(Ajustes!$A$3:$A$150,Medicamentos!B23,Ajustes!$E$3:$E$150) -> -66095 | G23: =E23-D23 -> -2 | H23: =IF(C23<>"",0,"") -> 0 | I23: =IF(AND(D23="0",E23="0"),"SI",IF(COUNTIF(Ajustes!$A$3:$A$150,B23),"SI",IF(AND(D23=0,E23=0,NOT(ISBLANK(D23)),NOT(ISBLANK(E23))),"SI",""))) -> SI
A24: A | B24: MICROSULES ARG. | C24: 45955 | D24: 360 | E24: 360 | F24: =SUMIF(Ajustes!$A$3:$A$150,Medicamentos!B24,Ajustes!$C$3:$C$150)+SUMIF(Ajustes!$A$3:$A$150,Medicamentos!B24,Ajustes!$E$3:$E$150) -> 45475.47 | G24: =E24-D24 -> 0 | H24: =IF(C24<>"",0,"") -> 0 | I24: =IF(AND(D24="0",E24="0"),"SI",IF(COUNTIF(Ajustes!$A$3:$A$150,B24),"SI",IF(AND(D24=0,E24=0,NOT(ISBLANK(D24)),NOT(ISBLANK(E24))),"SI",""))) -> SI
A25: A | B25: MONTPELLIER | F25: =SUMIF(Ajustes!$A$3:$A$150,Medicamentos!B25,Ajustes!$C$3:$C$150)+SUMIF(Ajustes!$A$3:$A$150,Medicamentos!B25,Ajustes!$E$3:$E$150) -> 0 | G25: =E25-D25 -> 0 | H25: =IF(C25<>"",0,"") | I25: =IF(AND(D25="0",E25="0"),"SI",IF(COUNTIF(Ajustes!$A$3:$A$150,B25),"SI",IF(AND(D25=0,E25=0,NOT(ISBLANK(D25)),NOT(ISBLANK(E25))),"SI","")))
A26: A | B26: NOVO NORDISK | C26: 45924 | D26: 265 | E26: 218 | F26: =SUMIF(Ajustes!$A$3:$A$150,Medicamentos!B26,Ajustes!$C$3:$C$150)+SUMIF(Ajustes!$A$3:$A$150,Medicamentos!B26,Ajustes!$E$3:$E$150) -> -6932.03 | G26: =E26-D26 -> -47 | H26: =IF(C26<>"",0,"") -> 0 | I26: =IF(AND(D26="0",E26="0"),"SI",IF(COUNTIF(Ajustes!$A$3:$A$150,B26),"SI",IF(AND(D26=0,E26=0,NOT(ISBLANK(D26)),NOT(ISBLANK(E26))),"SI",""))) -> SI
A27: A | B27: NUTRICIA-BAGÓ | C27: 45955 | D27: 292 | E27: 289 | F27: =SUMIF(Ajustes!$A$3:$A$150,Medicamentos!B27,Ajustes!$C$3:$C$150)+SUMIF(Ajustes!$A$3:$A$150,Medicamentos!B27,Ajustes!$E$3:$E$150) -> -213271.1 | G27: =E27-D27 -> -3 | H27: =IF(C27<>"",0,"") -> 0 | I27: =IF(AND(D27="0",E27="0"),"SI",IF(COUNTIF(Ajustes!$A$3:$A$150,B27),"SI",IF(AND(D27=0,E27=0,NOT(ISBLANK(D27)),NOT(ISBLANK(E27))),"SI",""))) -> SI
A28: A | B28: OPELLA HEALTHCA | C28: 45955 | D28: 145 | E28: 139 | F28: =SUMIF(Ajustes!$A$3:$A$150,Medicamentos!B28,Ajustes!$C$3:$C$150)+SUMIF(Ajustes!$A$3:$A$150,Medicamentos!B28,Ajustes!$E$3:$E$150) -> -278564.28 | G28: =E28-D28 -> -6 | H28: =IF(C28<>"",0,"") -> 0 | I28: =IF(AND(D28="0",E28="0"),"SI",IF(COUNTIF(Ajustes!$A$3:$A$150,B28),"SI",IF(AND(D28=0,E28=0,NOT(ISBLANK(D28)),NOT(ISBLANK(E28))),"SI",""))) -> SI
A29: A | B29: PANALAB | C29: 45923 | D29: 236 | E29: 236 | F29: =SUMIF(Ajustes!$A$3:$A$150,Medicamentos!B29,Ajustes!$C$3:$C$150)+SUMIF(Ajustes!$A$3:$A$150,Medicamentos!B29,Ajustes!$E$3:$E$150) -> 33686.58 | G29: =E29-D29 -> 0 | H29: =IF(C29<>"",0,"") -> 0 | I29: =IF(AND(D29="0",E29="0"),"SI",IF(COUNTIF(Ajustes!$A$3:$A$150,B29),"SI",IF(AND(D29=0,E29=0,NOT(ISBLANK(D29)),NOT(ISBLANK(E29))),"SI",""))) -> SI
A30: A | B30: PFIZER | C30: 45962 | D30: 0 | E30: 0 | F30: =SUMIF(Ajustes!$A$3:$A$150,Medicamentos!B30,Ajustes!$C$3:$C$150)+SUMIF(Ajustes!$A$3:$A$150,Medicamentos!B30,Ajustes!$E$3:$E$150) -> 0 | G30: =E30-D30 -> 0 | H30: =IF(C30<>"",0,"") -> 0 | I30: =IF(AND(D30="0",E30="0"),"SI",IF(COUNTIF(Ajustes!$A$3:$A$150,B30),"SI",IF(AND(D30=0,E30=0,NOT(ISBLANK(D30)),NOT(ISBLANK(E30))),"SI",""))) -> SI
A31: A | B31: POEN | C31: 45922 | D31: 248 | E31: 247 | F31: =SUMIF(Ajustes!$A$3:$A$150,Medicamentos!B31,Ajustes!$C$3:$C$150)+SUMIF(Ajustes!$A$3:$A$150,Medicamentos!B31,Ajustes!$E$3:$E$150) -> -29550.47 | G31: =E31-D31 -> -1 | H31: =IF(C31<>"",0,"") -> 0 | I31: =IF(AND(D31="0",E31="0"),"SI",IF(COUNTIF(Ajustes!$A$3:$A$150,B31),"SI",IF(AND(D31=0,E31=0,NOT(ISBLANK(D31)),NOT(ISBLANK(E31))),"SI",""))) -> SI
A32: A | B32: PROCTER & GAMBL | C32: 45953 | D32: 0 | E32: 0 | F32: =SUMIF(Ajustes!$A$3:$A$150,Medicamentos!B32,Ajustes!$C$3:$C$150)+SUMIF(Ajustes!$A$3:$A$150,Medicamentos!B32,Ajustes!$E$3:$E$150) -> 0 | G32: =E32-D32 -> 0 | H32: =IF(C32<>"",0,"") -> 0 | I32: =IF(AND(D32="0",E32="0"),"SI",IF(COUNTIF(Ajustes!$A$3:$A$150,B32),"SI",IF(AND(D32=0,E32=0,NOT(ISBLANK(D32)),NOT(ISBLANK(E32))),"SI",""))) -> SI
A33: A | B33: RAFFO | C33: 45957 | D33: 0 | E33: 0 | F33: =SUMIF(Ajustes!$A$3:$A$150,Medicamentos!B33,Ajustes!$C$3:$C$150)+SUMIF(Ajustes!$A$3:$A$150,Medicamentos!B33,Ajustes!$E$3:$E$150) -> 0 | G33: =E33-D33 -> 0 | H33: =IF(C33<>"",0,"") -> 0 | I33: =IF(AND(D33="0",E33="0"),"SI",IF(COUNTIF(Ajustes!$A$3:$A$150,B33),"SI",IF(AND(D33=0,E33=0,NOT(ISBLANK(D33)),NOT(ISBLANK(E33))),"SI",""))) -> SI
A34: A | B34: ROEMMERS | C34: 45960 | D34: 1092 | E34: 1088 | F34: =SUMIF(Ajustes!$A$3:$A$150,Medicamentos!B34,Ajustes!$C$3:$C$150)+SUMIF(Ajustes!$A$3:$A$150,Medicamentos!B34,Ajustes!$E$3:$E$150) -> -34484 | G34: =E34-D34 -> -4 | H34: =IF(C34<>"",0,"") -> 0 | I34: =IF(AND(D34="0",E34="0"),"SI",IF(COUNTIF(Ajustes!$A$3:$A$150,B34),"SI",IF(AND(D34=0,E34=0,NOT(ISBLANK(D34)),NOT(ISBLANK(E34))),"SI",""))) -> SI
A35: A | B35: SAVANT CONSUMER | C35: 45934 | D35: 327 | E35: 339 | F35: =SUMIF(Ajustes!$A$3:$A$150,Medicamentos!B35,Ajustes!$C$3:$C$150)+SUMIF(Ajustes!$A$3:$A$150,Medicamentos!B35,Ajustes!$E$3:$E$150) -> 60204.21 | G35: =E35-D35 -> 12 | H35: =IF(C35<>"",0,"") -> 0 | I35: =IF(AND(D35="0",E35="0"),"SI",IF(COUNTIF(Ajustes!$A$3:$A$150,B35),"SI",IF(AND(D35=0,E35=0,NOT(ISBLANK(D35)),NOT(ISBLANK(E35))),"SI",""))) -> SI
A36: A | B36: SIEGFRIED | C36: 45954 | D36: 425 | E36: 441 | F36: =SUMIF(Ajustes!$A$3:$A$150,Medicamentos!B36,Ajustes!$C$3:$C$150)+SUMIF(Ajustes!$A$3:$A$150,Medicamentos!B36,Ajustes!$E$3:$E$150) -> 415619.02 | G36: =E36-D36 -> 16 | H36: =IF(C36<>"",0,"") -> 0 | I36: =IF(AND(D36="0",E36="0"),"SI",IF(COUNTIF(Ajustes!$A$3:$A$150,B36),"SI",IF(AND(D36=0,E36=0,NOT(ISBLANK(D36)),NOT(ISBLANK(E36))),"SI",""))) -> SI
A37: A | B37: TEVA ARGENTINA | C37: 45934 | D37: 177 | E37: 169 | F37: =SUMIF(Ajustes!$A$3:$A$150,Medicamentos!B37,Ajustes!$C$3:$C$150)+SUMIF(Ajustes!$A$3:$A$150,Medicamentos!B37,Ajustes!$E$3:$E$150) -> -180393.37 | G37: =E37-D37 -> -8 | H37: =IF(C37<>"",0,"") -> 0 | I37: =IF(AND(D37="0",E37="0"),"SI",IF(COUNTIF(Ajustes!$A$3:$A$150,B37),"SI",IF(AND(D37=0,E37=0,NOT(ISBLANK(D37)),NOT(ISBLANK(E37))),"SI",""))) -> SI
... A95: C | B95: ASPEN ARGENTINA | C95: 45880 | D95: 0 | E95: 0 | F95: =SUMIF(Ajustes!$A$3:$A$150,Medicamentos!B95,Ajustes!$C$3:$C$150)+SUMIF(Ajustes!$A$3:$A$150,Medicamentos!B95,Ajustes!$E$3:$E$150) -> 0 | G95: =E95-D95 -> 0 | H95: =IF(C95<>"",0,"") -> 0 | I95: =IF(AND(D95="0",E95="0"),"SI",IF(COUNTIF(Ajustes!$A$3:$A$150,B95),"SI",IF(AND(D95=0,E95=0,NOT(ISBLANK(D95)),NOT(ISBLANK(E95))),"SI",""))) -> SI
A96: C | B96: BAJER | F96: =SUMIF(Ajustes!$A$3:$A$150,Medicamentos!B96,Ajustes!$C$3:$C$150)+SUMIF(Ajustes!$A$3:$A$150,Medicamentos!B96,Ajustes!$E$3:$E$150) -> 0 | G96: =E96-D96 -> 0 | H96: =IF(C96<>"",0,"") | I96: =IF(AND(D96="0",E96="0"),"SI",IF(COUNTIF(Ajustes!$A$3:$A$150,B96),"SI",IF(AND(D96=0,E96=0,NOT(ISBLANK(D96)),NOT(ISBLANK(E96))),"SI","")))
A97: C | B97: BIOPROFARMA BAG | C97: 45880 | D97: 0 | E97: 0 | F97: =SUMIF(Ajustes!$A$3:$A$150,Medicamentos!B97,Ajustes!$C$3:$C$150)+SUMIF(Ajustes!$A$3:$A$150,Medicamentos!B97,Ajustes!$E$3:$E$150) -> 0 | G97: =E97-D97 -> 0 | H97: =IF(C97<>"",0,"") -> 0 | I97: =IF(AND(D97="0",E97="0"),"SI",IF(COUNTIF(Ajustes!$A$3:$A$150,B97),"SI",IF(AND(D97=0,E97=0,NOT(ISBLANK(D97)),NOT(ISBLANK(E97))),"SI",""))) -> SI
A98: C | B98: BIOSIDUS S.A.U. | C98: 45913 | D98: 31 | E98: 31 | F98: =SUMIF(Ajustes!$A$3:$A$150,Medicamentos!B98,Ajustes!$C$3:$C$150)+SUMIF(Ajustes!$A$3:$A$150,Medicamentos!B98,Ajustes!$E$3:$E$150) -> 0 | G98: =E98-D98 -> 0 | H98: =IF(C98<>"",0,"") -> 0 | I98: =IF(AND(D98="0",E98="0"),"SI",IF(COUNTIF(Ajustes!$A$3:$A$150,B98),"SI",IF(AND(D98=0,E98=0,NOT(ISBLANK(D98)),NOT(ISBLANK(E98))),"SI",""))) -> SI
A99: C | B99: BIOTECHNO PHARM | C99: 45880 | D99: 0 | E99: 0 | F99: =SUMIF(Ajustes!$A$3:$A$150,Medicamentos!B99,Ajustes!$C$3:$C$150)+SUMIF(Ajustes!$A$3:$A$150,Medicamentos!B99,Ajustes!$E$3:$E$150) -> 0 | G99: =E99-D99 -> 0 | H99: =IF(C99<>"",0,"") -> 0 | I99: =IF(AND(D99="0",E99="0"),"SI",IF(COUNTIF(Ajustes!$A$3:$A$150,B99),"SI",IF(AND(D99=0,E99=0,NOT(ISBLANK(D99)),NOT(ISBLANK(E99))),"SI",""))) -> SI
A100: C | B100: BIOTOSCANA | C100: 45880 | D100: 0 | E100: 0 | F100: =SUMIF(Ajustes!$A$3:$A$150,Medicamentos!B100,Ajustes!$C$3:$C$150)+SUMIF(Ajustes!$A$3:$A$150,Medicamentos!B100,Ajustes!$E$3:$E$150) -> 0 | G100: =E100-D100 -> 0 | H100: =IF(C100<>"",0,"") -> 0 | I100: =IF(AND(D100="0",E100="0"),"SI",IF(COUNTIF(Ajustes!$A$3:$A$150,B100),"SI",IF(AND(D100=0,E100=0,NOT(ISBLANK(D100)),NOT(ISBLANK(E100))),"SI",""))) -> SI
A101: C | B101: B-LIFE | C101: 45880 | D101: 0 | E101: 0 | F101: =SUMIF(Ajustes!$A$3:$A$150,Medicamentos!B101,Ajustes!$C$3:$C$150)+SUMIF(Ajustes!$A$3:$A$150,Medicamentos!B101,Ajustes!$E$3:$E$150) -> 0 | G101: =E101-D101 -> 0 | H101: =IF(C101<>"",0,"") -> 0 | I101: =IF(AND(D101="0",E101="0"),"SI",IF(COUNTIF(Ajustes!$A$3:$A$150,B101),"SI",IF(AND(D101=0,E101=0,NOT(ISBLANK(D101)),NOT(ISBLANK(E101))),"SI",""))) -> SI
A102: C | B102: CABUCHI | C102: 45913 | D102: 3 | E102: 3 | F102: =SUMIF(Ajustes!$A$3:$A$150,Medicamentos!B102,Ajustes!$C$3:$C$150)+SUMIF(Ajustes!$A$3:$A$150,Medicamentos!B102,Ajustes!$E$3:$E$150) -> 0 | G102: =E102-D102 -> 0 | H102: =IF(C102<>"",0,"") -> 0 | I102: =IF(AND(D102="0",E102="0"),"SI",IF(COUNTIF(Ajustes!$A$3:$A$150,B102),"SI",IF(AND(D102=0,E102=0,NOT(ISBLANK(D102)),NOT(ISBLANK(E102))),"SI",""))) -> SI
A103: C | B103: CELNOVA ARGENTI | C103: 45913 | D103: 10 | E103: 10 | F103: =SUMIF(Ajustes!$A$3:$A$150,Medicamentos!B103,Ajustes!$C$3:$C$150)+SUMIF(Ajustes!$A$3:$A$150,Medicamentos!B103,Ajustes!$E$3:$E$150) -> 0 | G103: =E103-D103 -> 0 | H103: =IF(C103<>"",0,"") -> 0 | I103: =IF(AND(D103="0",E103="0"),"SI",IF(COUNTIF(Ajustes!$A$3:$A$150,B103),"SI",IF(AND(D103=0,E103=0,NOT(ISBLANK(D103)),NOT(ISBLANK(E103))),"SI",""))) -> SI
...

Sheet Perfumería
B2: Evolución de control Perfumería | E2: =IF('CONSOLIDADO - ALCANCE '!Z5>='CONSOLIDADO - ALCANCE '!M6,"PLANILLA FINALIZADA",IF('CONSOLIDADO - ALCANCE '!M3>0.09,CONCATENATE("Planilla Atrasada un ",TEXT('CONSOLIDADO - ALCANCE '!M3,"0%")),""))
C5: =COUNTIF(I10:I83,"Si")/B84 -> 1 | G5: =IF('CONSOLIDADO - ALCANCE '!D15<>"","Nuevo Aviso en la Primer Hoja","")
A9: Cluster | B9: Laboratorio | C9: Fecha de conteo | D9: Cajas | E9: Conteo Fisico | F9: Costo Dif | G9: Diferencias | H9: Chek | I9: Ajustado
A10: A | B10: BASICARE | C10: 45915 | D10: 28 | E10: 28 | F10: =SUMIF(Ajustes!$G$3:$G$150,Perfumería!B10,Ajustes!$I$3:$I$150)+SUMIF(Ajustes!$G$3:$G$150,Perfumería!B10,Ajustes!$K$3:$K$150) -> 0 | G10: =E10-D10 -> 0 | H10: =IF(C10<>"",0,"") -> 0 | I10: =IF(AND(D10="0",E10="0"),"SI",IF(COUNTIF(Ajustes!$G$3:$G$150,B10),"SI",IF(AND(D10=0,E10=0,NOT(ISBLANK(D10)),NOT(ISBLANK(E10))),"SI",""))) -> SI
A11: A | B11: BEIERSDORF | C11: 45912 | D11: 734 | E11: 734 | F11: =SUMIF(Ajustes!$G$3:$G$150,Perfumería!B11,Ajustes!$I$3:$I$150)+SUMIF(Ajustes!$G$3:$G$150,Perfumería!B11,Ajustes!$K$3:$K$150) -> 0 | G11: =E11-D11 -> 0 | H11: =IF(C11<>"",0,"") -> 0 | I11: =IF(AND(D11="0",E11="0"),"SI",IF(COUNTIF(Ajustes!$G$3:$G$150,B11),"SI",IF(AND(D11=0,E11=0,NOT(ISBLANK(D11)),NOT(ISBLANK(E11))),"SI",""))) -> SI
A12: A | B12: BUHL S.A | C12: 45923 | D12: 91 | E12: 91 | F12: =SUMIF(Ajustes!$G$3:$G$150,Perfumería!B12,Ajustes!$I$3:$I$150)+SUMIF(Ajustes!$G$3:$G$150,Perfumería!B12,Ajustes!$K$3:$K$150) -> 0 | G12: =E12-D12 -> 0 | H12: =IF(C12<>"",0,"") -> 0 | I12: =IF(AND(D12="0",E12="0"),"SI",IF(COUNTIF(Ajustes!$G$3:$G$150,B12),"SI",IF(AND(D12=0,E12=0,NOT(ISBLANK(D12)),NOT(ISBLANK(E12))),"SI",""))) -> SI
A13: A | B13: CANNON PUNTANA S.A. | C13: 45895 | D13: 346 | E13: 339 | F13: =SUMIF(Ajustes!$G$3:$G$150,Perfumería!B13,Ajustes!$I$3:$I$150)+SUMIF(Ajustes!$G$3:$G$150,Perfumería!B13,Ajustes!$K$3:$K$150) -> -21170.07 | G13: =E13-D13 -> -7 | H13: =IF(C13<>"",0,"") -> 0 | I13: =IF(AND(D13="0",E13="0"),"SI",IF(COUNTIF(Ajustes!$G$3:$G$150,B13),"SI",IF(AND(D13=0,E13=0,NOT(ISBLANK(D13)),NOT(ISBLANK(E13))),"SI",""))) -> SI
A14: A | B14: CAPILATIS | C14: 45923 | D14: 316 | E14: 316 | F14: =SUMIF(Ajustes!$G$3:$G$150,Perfumería!B14,Ajustes!$I$3:$I$150)+SUMIF(Ajustes!$G$3:$G$150,Perfumería!B14,Ajustes!$K$3:$K$150) -> 0 | G14: =E14-D14 -> 0 | H14: =IF(C14<>"",0,"") -> 0 | I14: =IF(AND(D14="0",E14="0"),"SI",IF(COUNTIF(Ajustes!$G$3:$G$150,B14),"SI",IF(AND(D14=0,E14=0,NOT(ISBLANK(D14)),NOT(ISBLANK(E14))),"SI",""))) -> SI
A15: A | B15: COLGATE | C15: 45913 | D15: 550 | E15: 550 | F15: =SUMIF(Ajustes!$G$3:$G$150,Perfumería!B15,Ajustes!$I$3:$I$150)+SUMIF(Ajustes!$G$3:$G$150,Perfumería!B15,Ajustes!$K$3:$K$150) -> 0 | G15: =E15-D15 -> 0 | H15: =IF(C15<>"",0,"") -> 0 | I15: =IF(AND(D15="0",E15="0"),"SI",IF(COUNTIF(Ajustes!$G$3:$G$150,B15),"SI",IF(AND(D15=0,E15=0,NOT(ISBLANK(D15)),NOT(ISBLANK(E15))),"SI",""))) -> SI
A16: A | B16: COTY ARGENTINA S.A. | C16: 45896 | D16: 96 | E16: 75 | F16: =SUMIF(Ajustes!$G$3:$G$150,Perfumería!B16,Ajustes!$I$3:$I$150)+SUMIF(Ajustes!$G$3:$G$150,Perfumería!B16,Ajustes!$K$3:$K$150) -> -396299.59 | G16: =E16-D16 -> -21 | H16: =IF(C16<>"",0,"") -> 0 | I16: =IF(AND(D16="0",E16="0"),"SI",IF(COUNTIF(Ajustes!$G$3:$G$150,B16),"SI",IF(AND(D16=0,E16=0,NOT(ISBLANK(D16)),NOT(ISBLANK(E16))),"SI",""))) -> SI
A17: A | B17: DISWALD | C17: 45922 | D17: 236 | E17: 236 | F17: =SUMIF(Ajustes!$G$3:$G$150,Perfumería!B17,Ajustes!$I$3:$I$150)+SUMIF(Ajustes!$G$3:$G$150,Perfumería!B17,Ajustes!$K$3:$K$150) -> 0 | G17: =E17-D17 -> 0 | H17: =IF(C17<>"",0,"") -> 0 | I17: =IF(AND(D17="0",E17="0"),"SI",IF(COUNTIF(Ajustes!$G$3:$G$150,B17),"SI",IF(AND(D17=0,E17=0,NOT(ISBLANK(D17)),NOT(ISBLANK(E17))),"SI",""))) -> SI
A18: A | B18: GILLETTE | C18: 45922 | D18: 94 | E18: 94 | F18: =SUMIF(Ajustes!$G$3:$G$150,Perfumería!B18,Ajustes!$I$3:$I$150)+SUMIF(Ajustes!$G$3:$G$150,Perfumería!B18,Ajustes!$K$3:$K$150) -> 0 | G18: =E18-D18 -> 0 | H18: =IF(C18<>"",0,"") -> 0 | I18: =IF(AND(D18="0",E18="0"),"SI",IF(COUNTIF(Ajustes!$G$3:$G$150,B18),"SI",IF(AND(D18=0,E18=0,NOT(ISBLANK(D18)),NOT(ISBLANK(E18))),"SI",""))) -> SI
A19: A | B19: GLAXOSMITHKLINE | C19: 45905 | D19: 190 | E19: 178 | F19: =SUMIF(Ajustes!$G$3:$G$150,Perfumería!B19,Ajustes!$I$3:$I$150)+SUMIF(Ajustes!$G$3:$G$150,Perfumería!B19,Ajustes!$K$3:$K$150) -> -149982.12 | G19: =E19-D19 -> -12 | H19: =IF(C19<>"",0,"") -> 0 | I19: =IF(AND(D19="0",E19="0"),"SI",IF(COUNTIF(Ajustes!$G$3:$G$150,B19),"SI",IF(AND(D19=0,E19=0,NOT(ISBLANK(D19)),NOT(ISBLANK(E19))),"SI",""))) -> SI
A20: A | B20: ISDIN | C20: 45922 | D20: 236 | E20: 236 | F20: =SUMIF(Ajustes!$G$3:$G$150,Perfumería!B20,Ajustes!$I$3:$I$150)+SUMIF(Ajustes!$G$3:$G$150,Perfumería!B20,Ajustes!$K$3:$K$150) -> 0 | G20: =E20-D20 -> 0 | H20: =IF(C20<>"",0,"") -> 0 | I20: =IF(AND(D20="0",E20="0"),"SI",IF(COUNTIF(Ajustes!$G$3:$G$150,B20),"SI",IF(AND(D20=0,E20=0,NOT(ISBLANK(D20)),NOT(ISBLANK(E20))),"SI",""))) -> SI
A21: A | B21: ISSUE | C21: 45922 | D21: 200 | E21: 200 | F21: =SUMIF(Ajustes!$G$3:$G$150,Perfumería!B21,Ajustes!$I$3:$I$150)+SUMIF(Ajustes!$G$3:$G$150,Perfumería!B21,Ajustes!$K$3:$K$150) -> 0 | G21: =E21-D21 -> 0 | H21: =IF(C21<>"",0,"") -> 0 | I21: =IF(AND(D21="0",E21="0"),"SI",IF(COUNTIF(Ajustes!$G$3:$G$150,B21),"SI",IF(AND(D21=0,E21=0,NOT(ISBLANK(D21)),NOT(ISBLANK(E21))),"SI",""))) -> SI
... A73: C | B73: WELEDA | C73: 45922 | D73: 15 | E73: 15 | F73: =SUMIF(Ajustes!$G$3:$G$150,Perfumería!B73,Ajustes!$I$3:$I$150)+SUMIF(Ajustes!$G$3:$G$150,Perfumería!B73,Ajustes!$K$3:$K$150) -> 0 | G73: =E73-D73 -> 0 | H73: =IF(C73<>"",0,"") -> 0 | I73: =IF(AND(D73="0",E73="0"),"SI",IF(COUNTIF(Ajustes!$G$3:$G$150,B73),"SI",IF(AND(D73=0,E73=0,NOT(ISBLANK(D73)),NOT(ISBLANK(E73))),"SI",""))) -> SI
F74: =SUMIF(Ajustes!$G$3:$G$150,Perfumería!B74,Ajustes!$I$3:$I$150)+SUMIF(Ajustes!$G$3:$G$150,Perfumería!B74,Ajustes!$K$3:$K$150) -> 0 | G74: =E74-D74 -> 0 | H74: =IF(C74<>"",0,"") | I74: =IF(AND(D74="0",E74="0"),"SI",IF(COUNTIF(Ajustes!$G$3:$G$150,B74),"SI",IF(AND(D74=0,E74=0,NOT(ISBLANK(D74)),NOT(ISBLANK(E74))),"SI","")))
F75: =SUMIF(Ajustes!$G$3:$G$150,Perfumería!B75,Ajustes!$I$3:$I$150)+SUMIF(Ajustes!$G$3:$G$150,Perfumería!B75,Ajustes!$K$3:$K$150) -> 0 | G75: =E75-D75 -> 0 | H75: =IF(C75<>"",0,"") | I75: =IF(AND(D75="0",E75="0"),"SI",IF(COUNTIF(Ajustes!$G$3:$G$150,B75),"SI",IF(AND(D75=0,E75=0,NOT(ISBLANK(D75)),NOT(ISBLANK(E75))),"SI","")))
F76: =SUMIF(Ajustes!$G$3:$G$150,Perfumería!B76,Ajustes!$I$3:$I$150)+SUMIF(Ajustes!$G$3:$G$150,Perfumería!B76,Ajustes!$K$3:$K$150) -> 0 | G76: =E76-D76 -> 0 | H76: =IF(C76<>"",0,"") | I76: =IF(AND(D76="0",E76="0"),"SI",IF(COUNTIF(Ajustes!$G$3:$G$150,B76),"SI",IF(AND(D76=0,E76=0,NOT(ISBLANK(D76)),NOT(ISBLANK(E76))),"SI","")))
F77: =SUMIF(Ajustes!$G$3:$G$150,Perfumería!B77,Ajustes!$I$3:$I$150)+SUMIF(Ajustes!$G$3:$G$150,Perfumería!B77,Ajustes!$K$3:$K$150) -> 0 | G77: =E77-D77 -> 0 | H77: =IF(C77<>"",0,"") | I77: =IF(AND(D77="0",E77="0"),"SI",IF(COUNTIF(Ajustes!$G$3:$G$150,B77),"SI",IF(AND(D77=0,E77=0,NOT(ISBLANK(D77)),NOT(ISBLANK(E77))),"SI","")))
F78: =SUMIF(Ajustes!$G$3:$G$150,Perfumería!B78,Ajustes!$I$3:$I$150)+SUMIF(Ajustes!$G$3:$G$150,Perfumería!B78,Ajustes!$K$3:$K$150) -> 0 | G78: =E78-D78 -> 0 | H78: =IF(C78<>"",0,"") | I78: =IF(AND(D78="0",E78="0"),"SI",IF(COUNTIF(Ajustes!$G$3:$G$150,B78),"SI",IF(AND(D78=0,E78=0,NOT(ISBLANK(D78)),NOT(ISBLANK(E78))),"SI","")))
F79: =SUMIF(Ajustes!$G$3:$G$150,Perfumería!B79,Ajustes!$I$3:$I$150)+SUMIF(Ajustes!$G$3:$G$150,Perfumería!B79,Ajustes!$K$3:$K$150) -> 0 | G79: =E79-D79 -> 0 | H79: =IF(C79<>"",0,"") | I79: =IF(AND(D79="0",E79="0"),"SI",IF(COUNTIF(Ajustes!$G$3:$G$150,B79),"SI",IF(AND(D79=0,E79=0,NOT(ISBLANK(D79)),NOT(ISBLANK(E79))),"SI","")))
F80: =SUMIF(Ajustes!$G$3:$G$150,Perfumería!B80,Ajustes!$I$3:$I$150)+SUMIF(Ajustes!$G$3:$G$150,Perfumería!B80,Ajustes!$K$3:$K$150) -> 0 | G80: =E80-D80 -> 0 | H80: =IF(C80<>"",0,"") | I80: =IF(AND(D80="0",E80="0"),"SI",IF(COUNTIF(Ajustes!$G$3:$G$150,B80),"SI",IF(AND(D80=0,E80=0,NOT(ISBLANK(D80)),NOT(ISBLANK(E80))),"SI","")))
F81: =SUMIF(Ajustes!$G$3:$G$150,Perfumería!B81,Ajustes!$I$3:$I$150)+SUMIF(Ajustes!$G$3:$G$150,Perfumería!B81,Ajustes!$K$3:$K$150) -> 0 | G81: =E81-D81 -> 0 | H81: =IF(C81<>"",0,"") | I81: =IF(AND(D81="0",E81="0"),"SI",IF(COUNTIF(Ajustes!$G$3:$G$150,B81),"SI",IF(AND(D81=0,E81=0,NOT(ISBLANK(D81)),NOT(ISBLANK(E81))),"SI","")))
F82: =SUMIF(Ajustes!$G$3:$G$150,Perfumería!B82,Ajustes!$I$3:$I$150)+SUMIF(Ajustes!$G$3:$G$150,Perfumería!B82,Ajustes!$K$3:$K$150) -> 0 | G82: =E82-D82 -> 0 | H82: =IF(C82<>"",0,"") | I82: =IF(AND(D82="0",E82="0"),"SI",IF(COUNTIF(Ajustes!$G$3:$G$150,B82),"SI",IF(AND(D82=0,E82=0,NOT(ISBLANK(D82)),NOT(ISBLANK(E82))),"SI","")))
F83: =SUMIF(Ajustes!$G$3:$G$150,Perfumería!B83,Ajustes!$I$3:$I$150)+SUMIF(Ajustes!$G$3:$G$150,Perfumería!B83,Ajustes!$K$3:$K$150) -> 0 | G83: =E83-D83 -> 0 | H83: =IF(C83<>"",0,"") | I83: =IF(AND(D83="0",E83="0"),"SI",IF(COUNTIF(Ajustes!$G$3:$G$150,B83),"SI",IF(AND(D83=0,E83=0,NOT(ISBLANK(D83)),NOT(ISBLANK(E83))),"SI","")))
B84: =COUNTA(B10:B83) -> 64 | C84: =COUNTA(C10:C83) -> 64 | D84: =SUM(D10:D83) -> 8600 | E84: =SUM(E10:E83) -> 8509 | F84: =SUM(F10:F83) -> -958277.64 | G84: =SUM(G10:G83) -> -91 | H84: =COUNTIF(H10:H83,0) -> 64 | I84: =COUNTIF(I10:I83,"Si")/64 -> 1

Sheet Accesorios
B2: Evolución de control Accesorios | E2: =IF('CONSOLIDADO - ALCANCE '!Z5>='CONSOLIDADO - ALCANCE '!M6,"PLANILLA FINALIZADA",IF('CONSOLIDADO - ALCANCE '!M3>0.09,CONCATENATE("Planilla Atrasada un ",TEXT('CONSOLIDADO - ALCANCE '!M3,"0%")),""))
C5: =COUNTIF(I10:I123,"Si")/B124 -> 0.99038462 | G5: =IF('CONSOLIDADO - ALCANCE '!D15<>"","Nuevo Aviso en la Primer Hoja","")
A9: Cluster | B9: Laboratorio | C9: Fecha de conteo | D9: Cajas | E9: Conteo Fisico | F9: Costo Total | G9: Diferencias | H9: Chek | I9: Ajustado
A10: A | B10: ANDRÓMACO | C10: 45945 | D10: 4 | E10: 4 | F10: =SUMIF(Ajustes!$M$3:$M$150,Accesorios!B10,Ajustes!$O$3:$O$150)+SUMIF(Ajustes!$M$3:$M$150,Accesorios!B10,Ajustes!$Q$3:$Q$150) -> 0 | G10: =E10-D10 -> 0 | H10: =IF(C10<>"",0,"") -> 0 | I10: =IF(AND(D10="0",E10="0"),"SI",IF(COUNTIF(Ajustes!$M$3:$M$150,B10),"SI",IF(AND(D10=0,E10=0,NOT(ISBLANK(D10)),NOT(ISBLANK(E10))),"SI",""))) -> SI
A11: A | B11: BAGÓ | C11: 45915 | D11: 298 | E11: 298 | F11: =SUMIF(Ajustes!$M$3:$M$150,Accesorios!B11,Ajustes!$O$3:$O$150)+SUMIF(Ajustes!$M$3:$M$150,Accesorios!B11,Ajustes!$Q$3:$Q$150) -> 0 | G11: =E11-D11 -> 0 | H11: =IF(C11<>"",0,"") -> 0 | I11: =IF(AND(D11="0",E11="0"),"SI",IF(COUNTIF(Ajustes!$M$3:$M$150,B11),"SI",IF(AND(D11=0,E11=0,NOT(ISBLANK(D11)),NOT(ISBLANK(E11))),"SI",""))) -> SI
A12: A | B12: BAUSCH & LOMB A | C12: 45941 | D12: 0 | E12: 0 | F12: =SUMIF(Ajustes!$M$3:$M$150,Accesorios!B12,Ajustes!$O$3:$O$150)+SUMIF(Ajustes!$M$3:$M$150,Accesorios!B12,Ajustes!$Q$3:$Q$150) -> 0 | G12: =E12-D12 -> 0 | H12: =IF(C12<>"",0,"") -> 0 | I12: =IF(AND(D12="0",E12="0"),"SI",IF(COUNTIF(Ajustes!$M$3:$M$150,B12),"SI",IF(AND(D12=0,E12=0,NOT(ISBLANK(D12)),NOT(ISBLANK(E12))),"SI",""))) -> SI
A13: A | B13: BEIERSDORF | C13: 45945 | D13: 295 | E13: 260 | F13: =SUMIF(Ajustes!$M$3:$M$150,Accesorios!B13,Ajustes!$O$3:$O$150)+SUMIF(Ajustes!$M$3:$M$150,Accesorios!B13,Ajustes!$Q$3:$Q$150) -> -116600 | G13: =E13-D13 -> -35 | H13: =IF(C13<>"",0,"") -> 0 | I13: =IF(AND(D13="0",E13="0"),"SI",IF(COUNTIF(Ajustes!$M$3:$M$150,B13),"SI",IF(AND(D13=0,E13=0,NOT(ISBLANK(D13)),NOT(ISBLANK(E13))),"SI",""))) -> SI
A14: A | B14: CEPAGE | C14: 45941 | D14: 0 | E14: 0 | F14: =SUMIF(Ajustes!$M$3:$M$150,Accesorios!B14,Ajustes!$O$3:$O$150)+SUMIF(Ajustes!$M$3:$M$150,Accesorios!B14,Ajustes!$Q$3:$Q$150) -> 0 | G14: =E14-D14 -> 0 | H14: =IF(C14<>"",0,"") -> 0 | I14: =IF(AND(D14="0",E14="0"),"SI",IF(COUNTIF(Ajustes!$M$3:$M$150,B14),"SI",IF(AND(D14=0,E14=0,NOT(ISBLANK(D14)),NOT(ISBLANK(E14))),"SI",""))) -> SI
A15: A | B15: ELEA | C15: 45945 | D15: 174 | E15: 171 | F15: =SUMIF(Ajustes!$M$3:$M$150,Accesorios!B15,Ajustes!$O$3:$O$150)+SUMIF(Ajustes!$M$3:$M$150,Accesorios!B15,Ajustes!$Q$3:$Q$150) -> -55897.7 | G15: =E15-D15 -> -3 | H15: =IF(C15<>"",0,"") -> 0 | I15: =IF(AND(D15="0",E15="0"),"SI",IF(COUNTIF(Ajustes!$M$3:$M$150,B15),"SI",IF(AND(D15=0,E15=0,NOT(ISBLANK(D15)),NOT(ISBLANK(E15))),"SI",""))) -> SI
A16: A | B16: EUROLAB | C16: 45945 | D16: 18 | E16: 18 | F16: =SUMIF(Ajustes!$M$3:$M$150,Accesorios!B16,Ajustes!$O$3:$O$150)+SUMIF(Ajustes!$M$3:$M$150,Accesorios!B16,Ajustes!$Q$3:$Q$150) -> 0 | G16: =E16-D16 -> 0 | H16: =IF(C16<>"",0,"") -> 0 | I16: =IF(AND(D16="0",E16="0"),"SI",IF(COUNTIF(Ajustes!$M$3:$M$150,B16),"SI",IF(AND(D16=0,E16=0,NOT(ISBLANK(D16)),NOT(ISBLANK(E16))),"SI","")))
A17: A | B17: EXIMIA | C17: 45915 | D17: 114 | E17: 116 | F17: =SUMIF(Ajustes!$M$3:$M$150,Accesorios!B17,Ajustes!$O$3:$O$150)+SUMIF(Ajustes!$M$3:$M$150,Accesorios!B17,Ajustes!$Q$3:$Q$150) -> 77700.08 | G17: =E17-D17 -> 2 | H17: =IF(C17<>"",0,"") -> 0 | I17: =IF(AND(D17="0",E17="0"),"SI",IF(COUNTIF(Ajustes!$M$3:$M$150,B17),"SI",IF(AND(D17=0,E17=0,NOT(ISBLANK(D17)),NOT(ISBLANK(E17))),"SI",""))) -> SI
A18: A | B18: GALDERMA | C18: 45941 | D18: 0 | E18: 0 | F18: =SUMIF(Ajustes!$M$3:$M$150,Accesorios!B18,Ajustes!$O$3:$O$150)+SUMIF(Ajustes!$M$3:$M$150,Accesorios!B18,Ajustes!$Q$3:$Q$150) -> 0 | G18: =E18-D18 -> 0 | H18: =IF(C18<>"",0,"") -> 0 | I18: =IF(AND(D18="0",E18="0"),"SI",IF(COUNTIF(Ajustes!$M$3:$M$150,B18),"SI",IF(AND(D18=0,E18=0,NOT(ISBLANK(D18)),NOT(ISBLANK(E18))),"SI",""))) -> SI
A19: A | B19: GENOMMA LAB. | C19: 45941 | D19: 0 | E19: 0 | F19: =SUMIF(Ajustes!$M$3:$M$150,Accesorios!B19,Ajustes!$O$3:$O$150)+SUMIF(Ajustes!$M$3:$M$150,Accesorios!B19,Ajustes!$Q$3:$Q$150) -> 0 | G19: =E19-D19 -> 0 | H19: =IF(C19<>"",0,"") -> 0 | I19: =IF(AND(D19="0",E19="0"),"SI",IF(COUNTIF(Ajustes!$M$3:$M$150,B19),"SI",IF(AND(D19=0,E19=0,NOT(ISBLANK(D19)),NOT(ISBLANK(E19))),"SI",""))) -> SI
A20: A | B20: GRIMBERG | C20: 45944 | D20: 53 | E20: 53 | F20: =SUMIF(Ajustes!$M$3:$M$150,Accesorios!B20,Ajustes!$O$3:$O$150)+SUMIF(Ajustes!$M$3:$M$150,Accesorios!B20,Ajustes!$Q$3:$Q$150) -> 0 | G20: =E20-D20 -> 0 | H20: =IF(C20<>"",0,"") -> 0 | I20: =IF(AND(D20="0",E20="0"),"SI",IF(COUNTIF(Ajustes!$M$3:$M$150,B20),"SI",IF(AND(D20=0,E20=0,NOT(ISBLANK(D20)),NOT(ISBLANK(E20))),"SI",""))) -> SI
A21: A | B21: LAB. AZUL | C21: 45944 | D21: 3 | E21: 7 | F21: =SUMIF(Ajustes!$M$3:$M$150,Accesorios!B21,Ajustes!$O$3:$O$150)+SUMIF(Ajustes!$M$3:$M$150,Accesorios!B21,Ajustes!$Q$3:$Q$150) -> 2926.08 | G21: =E21-D21 -> 4 | H21: =IF(C21<>"",0,"") -> 0 | I21: =IF(AND(D21="0",E21="0"),"SI",IF(COUNTIF(Ajustes!$M$3:$M$150,B21),"SI",IF(AND(D21=0,E21=0,NOT(ISBLANK(D21)),NOT(ISBLANK(E21))),"SI",""))) -> SI
... A113: C | B113: WERFEN MEDICAL | C113: 45936 | D113: 59 | E113: 49 | F113: =SUMIF(Ajustes!$M$3:$M$150,Accesorios!B113,Ajustes!$O$3:$O$150)+SUMIF(Ajustes!$M$3:$M$150,Accesorios!B113,Ajustes!$Q$3:$Q$150) -> -165847.03 | G113: =E113-D113 -> -10 | H113: =IF(C113<>"",0,"") -> 0 | I113: =IF(AND(D113="0",E113="0"),"SI",IF(COUNTIF(Ajustes!$M$3:$M$150,B113),"SI",IF(AND(D113=0,E113=0,NOT(ISBLANK(D113)),NOT(ISBLANK(E113))),"SI",""))) -> SI
F114: =SUMIF(Ajustes!$M$3:$M$150,Accesorios!B114,Ajustes!$O$3:$O$150)+SUMIF(Ajustes!$M$3:$M$150,Accesorios!B114,Ajustes!$Q$3:$Q$150) -> 0 | G114: =E114-D114 -> 0 | H114: =IF(C114<>"",0,"") | I114: =IF(AND(D114="0",E114="0"),"SI",IF(COUNTIF(Ajustes!$M$3:$M$150,B114),"SI",IF(AND(D114=0,E114=0,NOT(ISBLANK(D114)),NOT(ISBLANK(E114))),"SI","")))
F115: =SUMIF(Ajustes!$M$3:$M$150,Accesorios!B115,Ajustes!$O$3:$O$150)+SUMIF(Ajustes!$M$3:$M$150,Accesorios!B115,Ajustes!$Q$3:$Q$150) -> 0 | G115: =E115-D115 -> 0 | H115: =IF(C115<>"",0,"") | I115: =IF(AND(D115="0",E115="0"),"SI",IF(COUNTIF(Ajustes!$M$3:$M$150,B115),"SI",IF(AND(D115=0,E115=0,NOT(ISBLANK(D115)),NOT(ISBLANK(E115))),"SI","")))
F116: =SUMIF(Ajustes!$M$3:$M$150,Accesorios!B116,Ajustes!$O$3:$O$150)+SUMIF(Ajustes!$M$3:$M$150,Accesorios!B116,Ajustes!$Q$3:$Q$150) -> 0 | G116: =E116-D116 -> 0 | H116: =IF(C116<>"",0,"") | I116: =IF(AND(D116="0",E116="0"),"SI",IF(COUNTIF(Ajustes!$M$3:$M$150,B116),"SI",IF(AND(D116=0,E116=0,NOT(ISBLANK(D116)),NOT(ISBLANK(E116))),"SI","")))
F117: =SUMIF(Ajustes!$M$3:$M$150,Accesorios!B117,Ajustes!$O$3:$O$150)+SUMIF(Ajustes!$M$3:$M$150,Accesorios!B117,Ajustes!$Q$3:$Q$150) -> 0 | G117: =E117-D117 -> 0 | H117: =IF(C117<>"",0,"") | I117: =IF(AND(D117="0",E117="0"),"SI",IF(COUNTIF(Ajustes!$M$3:$M$150,B117),"SI",IF(AND(D117=0,E117=0,NOT(ISBLANK(D117)),NOT(ISBLANK(E117))),"SI","")))
F118: =SUMIF(Ajustes!$M$3:$M$150,Accesorios!B118,Ajustes!$O$3:$O$150)+SUMIF(Ajustes!$M$3:$M$150,Accesorios!B118,Ajustes!$Q$3:$Q$150) -> 0 | G118: =E118-D118 -> 0 | H118: =IF(C118<>"",0,"") | I118: =IF(AND(D118="0",E118="0"),"SI",IF(COUNTIF(Ajustes!$M$3:$M$150,B118),"SI",IF(AND(D118=0,E118=0,NOT(ISBLANK(D118)),NOT(ISBLANK(E118))),"SI","")))
F119: =SUMIF(Ajustes!$M$3:$M$150,Accesorios!B119,Ajustes!$O$3:$O$150)+SUMIF(Ajustes!$M$3:$M$150,Accesorios!B119,Ajustes!$Q$3:$Q$150) -> 0 | G119: =E119-D119 -> 0 | H119: =IF(C119<>"",0,"") | I119: =IF(AND(D119="0",E119="0"),"SI",IF(COUNTIF(Ajustes!$M$3:$M$150,B119),"SI",IF(AND(D119=0,E119=0,NOT(ISBLANK(D119)),NOT(ISBLANK(E119))),"SI","")))
F120: =SUMIF(Ajustes!$M$3:$M$150,Accesorios!B120,Ajustes!$O$3:$O$150)+SUMIF(Ajustes!$M$3:$M$150,Accesorios!B120,Ajustes!$Q$3:$Q$150) -> 0 | G120: =E120-D120 -> 0 | H120: =IF(C120<>"",0,"") | I120: =IF(AND(D120="0",E120="0"),"SI",IF(COUNTIF(Ajustes!$M$3:$M$150,B120),"SI",IF(AND(D120=0,E120=0,NOT(ISBLANK(D120)),NOT(ISBLANK(E120))),"SI","")))
F121: =SUMIF(Ajustes!$M$3:$M$150,Accesorios!B121,Ajustes!$O$3:$O$150)+SUMIF(Ajustes!$M$3:$M$150,Accesorios!B121,Ajustes!$Q$3:$Q$150) -> 0 | G121: =E121-D121 -> 0 | H121: =IF(C121<>"",0,"") | I121: =IF(AND(D121="0",E121="0"),"SI",IF(COUNTIF(Ajustes!$M$3:$M$150,B121),"SI",IF(AND(D121=0,E121=0,NOT(ISBLANK(D121)),NOT(ISBLANK(E121))),"SI","")))
F122: =SUMIF(Ajustes!$M$3:$M$150,Accesorios!B122,Ajustes!$O$3:$O$150)+SUMIF(Ajustes!$M$3:$M$150,Accesorios!B122,Ajustes!$Q$3:$Q$150) -> 0 | G122: =E122-D122 -> 0 | H122: =IF(C122<>"",0,"") | I122: =IF(AND(D122="0",E122="0"),"SI",IF(COUNTIF(Ajustes!$M$3:$M$150,B122),"SI",IF(AND(D122=0,E122=0,NOT(ISBLANK(D122)),NOT(ISBLANK(E122))),"SI","")))
F123: =SUMIF(Ajustes!$M$3:$M$150,Accesorios!B123,Ajustes!$O$3:$O$150)+SUMIF(Ajustes!$M$3:$M$150,Accesorios!B123,Ajustes!$Q$3:$Q$150) -> 0 | G123: =E123-D123 -> 0 | H123: =IF(C123<>"",0,"") | I123: =IF(AND(D123="0",E123="0"),"SI",IF(COUNTIF(Ajustes!$M$3:$M$150,B123),"SI",IF(AND(D123=0,E123=0,NOT(ISBLANK(D123)),NOT(ISBLANK(E123))),"SI","")))
B124: =COUNTA(B10:B123) -> 104 | C124: =COUNTA(C10:C123) -> 104 | D124: =SUM(D10:D123) -> 2103 | E124: =SUM(E10:E123) -> 1948 | F124: =SUM(F10:F123) -> -189296.57 | G124: =SUM(G10:G123) -> -155 | H124: =COUNTIF(H10:H123,0) -> 104 | I124: =COUNTIF(I10:I123,"Si")/104 -> 0.99038462

Sheet Varios
B2: Evolución de control Varios | E2: =IF('CONSOLIDADO - ALCANCE '!Z5>='CONSOLIDADO - ALCANCE '!M6,"PLANILLA FINALIZADA",IF('CONSOLIDADO - ALCANCE '!M3>0.09,CONCATENATE("Planilla Atrasada un ",TEXT('CONSOLIDADO - ALCANCE '!M3,"0%")),""))
C5: =COUNTIF(I10:I45,"Si")/B46 -> 0.76923077 | G5: =IF('CONSOLIDADO - ALCANCE '!D15<>"","Nuevo Aviso en la Primer Hoja","")
A9: Cluster | B9: Laboratorio | C9: Fecha de conteo | D9: Cajas | E9: Conteo Fisico | F9: Costo Total | G9: Diferencias | H9: Chek | I9: Ajustado
A10: A | B10: ALCON | C10: 45941 | D10: 0 | E10: 0 | F10: =SUMIF(Ajustes!$S$3:$S$150,Varios!B10,Ajustes!$U$3:$U$150)+SUMIF(Ajustes!$S$3:$S$150,Varios!B10,Ajustes!W$3:$W$150) -> 0 | G10: =E10-D10 -> 0 | H10: =IF(C10<>"",0,"") -> 0 | I10: =IF(AND(D10="0",E10="0"),"SI",IF(COUNTIF(Ajustes!$S$3:$S$150,B10),"SI",IF(AND(D10=0,E10=0,NOT(ISBLANK(D10)),NOT(ISBLANK(E10))),"SI",""))) -> SI
A11: A | B11: ARCOR | F11: =SUMIF(Ajustes!$S$3:$S$150,Varios!B11,Ajustes!$U$3:$U$150)+SUMIF(Ajustes!$S$3:$S$150,Varios!B11,Ajustes!W$3:$W$150) -> 0 | G11: =E11-D11 -> 0 | H11: =IF(C11<>"",0,"") | I11: =IF(AND(D11="0",E11="0"),"SI",IF(COUNTIF(Ajustes!$S$3:$S$150,B11),"SI",IF(AND(D11=0,E11=0,NOT(ISBLANK(D11)),NOT(ISBLANK(E11))),"SI","")))
A12: A | B12: BAUSCH & LOMB A | C12: 45957 | D12: 0 | E12: 0 | F12: =SUMIF(Ajustes!$S$3:$S$150,Varios!B12,Ajustes!$U$3:$U$150)+SUMIF(Ajustes!$S$3:$S$150,Varios!B12,Ajustes!W$3:$W$150) -> 0 | G12: =E12-D12 -> 0 | H12: =IF(C12<>"",0,"") -> 0 | I12: =IF(AND(D12="0",E12="0"),"SI",IF(COUNTIF(Ajustes!$S$3:$S$150,B12),"SI",IF(AND(D12=0,E12=0,NOT(ISBLANK(D12)),NOT(ISBLANK(E12))),"SI",""))) -> SI
A13: A | B13: CAPALBO | F13: =SUMIF(Ajustes!$S$3:$S$150,Varios!B13,Ajustes!$U$3:$U$150)+SUMIF(Ajustes!$S$3:$S$150,Varios!B13,Ajustes!W$3:$W$150) -> 0 | G13: =E13-D13 -> 0 | H13: =IF(C13<>"",0,"") | I13: =IF(AND(D13="0",E13="0"),"SI",IF(COUNTIF(Ajustes!$S$3:$S$150,B13),"SI",IF(AND(D13=0,E13=0,NOT(ISBLANK(D13)),NOT(ISBLANK(E13))),"SI","")))
A14: A | B14: COCA COLA / FEMSA | C14: 45934 | D14: 382 | E14: 348 | F14: =SUMIF(Ajustes!$S$3:$S$150,Varios!B14,Ajustes!$U$3:$U$150)+SUMIF(Ajustes!$S$3:$S$150,Varios!B14,Ajustes!W$3:$W$150) -> -45124.02 | G14: =E14-D14 -> -34 | H14: =IF(C14<>"",0,"") -> 0 | I14: =IF(AND(D14="0",E14="0"),"SI",IF(COUNTIF(Ajustes!$S$3:$S$150,B14),"SI",IF(AND(D14=0,E14=0,NOT(ISBLANK(D14)),NOT(ISBLANK(E14))),"SI",""))) -> SI
A15: A | B15: ELITE | C15: 45938 | D15: 91 | E15: 42 | F15: =SUMIF(Ajustes!$S$3:$S$150,Varios!B15,Ajustes!$U$3:$U$150)+SUMIF(Ajustes!$S$3:$S$150,Varios!B15,Ajustes!W$3:$W$150) -> -33399.95 | G15: =E15-D15 -> -49 | H15: =IF(C15<>"",0,"") -> 0 | I15: =IF(AND(D15="0",E15="0"),"SI",IF(COUNTIF(Ajustes!$S$3:$S$150,B15),"SI",IF(AND(D15=0,E15=0,NOT(ISBLANK(D15)),NOT(ISBLANK(E15))),"SI",""))) -> SI
A16: A | B16: ENERGIZER ARGENTINA S.A. | C16: 45934 | D16: 1 | E16: 1 | F16: =SUMIF(Ajustes!$S$3:$S$150,Varios!B16,Ajustes!$U$3:$U$150)+SUMIF(Ajustes!$S$3:$S$150,Varios!B16,Ajustes!W$3:$W$150) -> 0 | G16: =E16-D16 -> 0 | H16: =IF(C16<>"",0,"") -> 0 | I16: =IF(AND(D16="0",E16="0"),"SI",IF(COUNTIF(Ajustes!$S$3:$S$150,B16),"SI",IF(AND(D16=0,E16=0,NOT(ISBLANK(D16)),NOT(ISBLANK(E16))),"SI",""))) -> SI
A17: A | B17: FELFORT | C17: 45955 | D17: 199 | E17: 3 | F17: =SUMIF(Ajustes!$S$3:$S$150,Varios!B17,Ajustes!$U$3:$U$150)+SUMIF(Ajustes!$S$3:$S$150,Varios!B17,Ajustes!W$3:$W$150) -> -495205.92 | G17: =E17-D17 -> -196 | H17: =IF(C17<>"",0,"") -> 0 | I17: =IF(AND(D17="0",E17="0"),"SI",IF(COUNTIF(Ajustes!$S$3:$S$150,B17),"SI",IF(AND(D17=0,E17=0,NOT(ISBLANK(D17)),NOT(ISBLANK(E17))),"SI",""))) -> SI
A18: A | B18: GILLETTE | C18: 45941 | D18: 0 | E18: 0 | F18: =SUMIF(Ajustes!$S$3:$S$150,Varios!B18,Ajustes!$U$3:$U$150)+SUMIF(Ajustes!$S$3:$S$150,Varios!B18,Ajustes!W$3:$W$150) -> 0 | G18: =E18-D18 -> 0 | H18: =IF(C18<>"",0,"") -> 0 | I18: =IF(AND(D18="0",E18="0"),"SI",IF(COUNTIF(Ajustes!$S$3:$S$150,B18),"SI",IF(AND(D18=0,E18=0,NOT(ISBLANK(D18)),NOT(ISBLANK(E18))),"SI",""))) -> SI
A19: A | B19: GRIMBERG | C19: 45941 | D19: 0 | E19: 0 | F19: =SUMIF(Ajustes!$S$3:$S$150,Varios!B19,Ajustes!$U$3:$U$150)+SUMIF(Ajustes!$S$3:$S$150,Varios!B19,Ajustes!W$3:$W$150) -> 0 | G19: =E19-D19 -> 0 | H19: =IF(C19<>"",0,"") -> 0 | I19: =IF(AND(D19="0",E19="0"),"SI",IF(COUNTIF(Ajustes!$S$3:$S$150,B19),"SI",IF(AND(D19=0,E19=0,NOT(ISBLANK(D19)),NOT(ISBLANK(E19))),"SI",""))) -> SI
A20: A | B20: HOME 2000 S.A. | C20: 45957 | D20: 21 | E20: 8 | F20: =SUMIF(Ajustes!$S$3:$S$150,Varios!B20,Ajustes!$U$3:$U$150)+SUMIF(Ajustes!$S$3:$S$150,Varios!B20,Ajustes!W$3:$W$150) -> -107320.69 | G20: =E20-D20 -> -13 | H20: =IF(C20<>"",0,"") -> 0 | I20: =IF(AND(D20="0",E20="0"),"SI",IF(COUNTIF(Ajustes!$S$3:$S$150,B20),"SI",IF(AND(D20=0,E20=0,NOT(ISBLANK(D20)),NOT(ISBLANK(E20))),"SI",""))) -> SI
A21: A | B21: INSBRUCK | C21: 45957 | D21: 212 | E21: 201 | F21: =SUMIF(Ajustes!$S$3:$S$150,Varios!B21,Ajustes!$U$3:$U$150)+SUMIF(Ajustes!$S$3:$S$150,Varios!B21,Ajustes!W$3:$W$150) -> -85265.57 | G21: =E21-D21 -> -11 | H21: =IF(C21<>"",0,"") -> 0 | I21: =IF(AND(D21="0",E21="0"),"SI",IF(COUNTIF(Ajustes!$S$3:$S$150,B21),"SI",IF(AND(D21=0,E21=0,NOT(ISBLANK(D21)),NOT(ISBLANK(E21))),"SI",""))) -> SI
A22: A | B22: JOHNSON & JOHNS | C22: 45957 | D22: 2 | E22: 2 | F22: =SUMIF(Ajustes!$S$3:$S$150,Varios!B22,Ajustes!$U$3:$U$150)+SUMIF(Ajustes!$S$3:$S$150,Varios!B22,Ajustes!W$3:$W$150) -> 0 | G22: =E22-D22 -> 0 | H22: =IF(C22<>"",0,"") -> 0 | I22: =IF(AND(D22="0",E22="0"),"SI",IF(COUNTIF(Ajustes!$S$3:$S$150,B22),"SI",IF(AND(D22=0,E22=0,NOT(ISBLANK(D22)),NOT(ISBLANK(E22))),"SI",""))) -> SI
A23: A | B23: KRAFT FOODS | C23: 45947 | D23: 2010 | E23: 1805 | F23: =SUMIF(Ajustes!$S$3:$S$150,Varios!B23,Ajustes!$U$3:$U$150)+SUMIF(Ajustes!$S$3:$S$150,Varios!B23,Ajustes!W$3:$W$150) -> -498127.63 | G23: =E23-D23 -> -205 | H23: =IF(C23<>"",0,"") -> 0 | I23: =IF(AND(D23="0",E23="0"),"SI",IF(COUNTIF(Ajustes!$S$3:$S$150,B23),"SI",IF(AND(D23=0,E23=0,NOT(ISBLANK(D23)),NOT(ISBLANK(E23))),"SI",""))) -> SI
A24: A | B24: LA PAPELERA DEL PLATA S A | C24: 45941 | D24: 0 | E24: 0 | F24: =SUMIF(Ajustes!$S$3:$S$150,Varios!B24,Ajustes!$U$3:$U$150)+SUMIF(Ajustes!$S$3:$S$150,Varios!B24,Ajustes!W$3:$W$150) -> 0 | G24: =E24-D24 -> 0 | H24: =IF(C24<>"",0,"") -> 0 | I24: =IF(AND(D24="0",E24="0"),"SI",IF(COUNTIF(Ajustes!$S$3:$S$150,B24),"SI",IF(AND(D24=0,E24=0,NOT(ISBLANK(D24)),NOT(ISBLANK(E24))),"SI",""))) -> SI
A25: A | B25: LAB. AZUL | F25: =SUMIF(Ajustes!$S$3:$S$150,Varios!B25,Ajustes!$U$3:$U$150)+SUMIF(Ajustes!$S$3:$S$150,Varios!B25,Ajustes!W$3:$W$150) -> 0 | G25: =E25-D25 -> 0 | H25: =IF(C25<>"",0,"") | I25: =IF(AND(D25="0",E25="0"),"SI",IF(COUNTIF(Ajustes!$S$3:$S$150,B25),"SI",IF(AND(D25=0,E25=0,NOT(ISBLANK(D25)),NOT(ISBLANK(E25))),"SI","")))
A26: A | B26: LABORATORIOS DIRAL SRL | C26: 45957 | D26: 49 | E26: 48 | F26: =SUMIF(Ajustes!$S$3:$S$150,Varios!B26,Ajustes!$U$3:$U$150)+SUMIF(Ajustes!$S$3:$S$150,Varios!B26,Ajustes!W$3:$W$150) -> -4369.3 | G26: =E26-D26 -> -1 | H26: =IF(C26<>"",0,"") -> 0 | I26: =IF(AND(D26="0",E26="0"),"SI",IF(COUNTIF(Ajustes!$S$3:$S$150,B26),"SI",IF(AND(D26=0,E26=0,NOT(ISBLANK(D26)),NOT(ISBLANK(E26))),"SI",""))) -> SI
A27: A | B27: OMRON | C27: 45957 | D27: 5 | E27: 5 | F27: =SUMIF(Ajustes!$S$3:$S$150,Varios!B27,Ajustes!$U$3:$U$150)+SUMIF(Ajustes!$S$3:$S$150,Varios!B27,Ajustes!W$3:$W$150) -> 0 | G27: =E27-D27 -> 0 | H27: =IF(C27<>"",0,"") -> 0 | I27: =IF(AND(D27="0",E27="0"),"SI",IF(COUNTIF(Ajustes!$S$3:$S$150,B27),"SI",IF(AND(D27=0,E27=0,NOT(ISBLANK(D27)),NOT(ISBLANK(E27))),"SI",""))) -> SI
A28: A | B28: PAPELERA DEL PLATA | C28: 45941 | D28: 0 | E28: 0 | F28: =SUMIF(Ajustes!$S$3:$S$150,Varios!B28,Ajustes!$U$3:$U$150)+SUMIF(Ajustes!$S$3:$S$150,Varios!B28,Ajustes!W$3:$W$150) -> 0 | G28: =E28-D28 -> 0 | H28: =IF(C28<>"",0,"") -> 0 | I28: =IF(AND(D28="0",E28="0"),"SI",IF(COUNTIF(Ajustes!$S$3:$S$150,B28),"SI",IF(AND(D28=0,E28=0,NOT(ISBLANK(D28)),NOT(ISBLANK(E28))),"SI",""))) -> SI
A29: A | B29: PHARMAMERICAN S | C29: 45957 | D29: 1 | E29: 1 | F29: =SUMIF(Ajustes!$S$3:$S$150,Varios!B29,Ajustes!$U$3:$U$150)+SUMIF(Ajustes!$S$3:$S$150,Varios!B29,Ajustes!W$3:$W$150) -> 0 | G29: =E29-D29 -> 0 | H29: =IF(C29<>"",0,"") -> 0 | I29: =IF(AND(D29="0",E29="0"),"SI",IF(COUNTIF(Ajustes!$S$3:$S$150,B29),"SI",IF(AND(D29=0,E29=0,NOT(ISBLANK(D29)),NOT(ISBLANK(E29))),"SI",""))) -> SI
A30: A | B30: SIN CLASIFICAR | F30: =SUMIF(Ajustes!$S$3:$S$150,Varios!B30,Ajustes!$U$3:$U$150)+SUMIF(Ajustes!$S$3:$S$150,Varios!B30,Ajustes!W$3:$W$150) -> 0 | G30: =E30-D30 -> 0 | H30: =IF(C30<>"",0,"") | I30: =IF(AND(D30="0",E30="0"),"SI",IF(COUNTIF(Ajustes!$S$3:$S$150,B30),"SI",IF(AND(D30=0,E30=0,NOT(ISBLANK(D30)),NOT(ISBLANK(E30))),"SI","")))
A31: A | B31: SIN LABORATORIO | F31: =SUMIF(Ajustes!$S$3:$S$150,Varios!B31,Ajustes!$U$3:$U$150)+SUMIF(Ajustes!$S$3:$S$150,Varios!B31,Ajustes!W$3:$W$150) -> 0 | G31: =E31-D31 -> 0 | H31: =IF(C31<>"",0,"") | I31: =IF(AND(D31="0",E31="0"),"SI",IF(COUNTIF(Ajustes!$S$3:$S$150,B31),"SI",IF(AND(D31=0,E31=0,NOT(ISBLANK(D31)),NOT(ISBLANK(E31))),"SI","")))
A32: A | B32: STELLA | C32: 45941 | D32: 0 | E32: 0 | F32: =SUMIF(Ajustes!$S$3:$S$150,Varios!B32,Ajustes!$U$3:$U$150)+SUMIF(Ajustes!$S$3:$S$150,Varios!B32,Ajustes!W$3:$W$150) -> 0 | G32: =E32-D32 -> 0 | H32: =IF(C32<>"",0,"") -> 0 | I32: =IF(AND(D32="0",E32="0"),"SI",IF(COUNTIF(Ajustes!$S$3:$S$150,B32),"SI",IF(AND(D32=0,E32=0,NOT(ISBLANK(D32)),NOT(ISBLANK(E32))),"SI",""))) -> SI
A33: A | B33: UNILEVER | C33: 45941 | D33: 0 | E33: 0 | F33: =SUMIF(Ajustes!$S$3:$S$150,Varios!B33,Ajustes!$U$3:$U$150)+SUMIF(Ajustes!$S$3:$S$150,Varios!B33,Ajustes!W$3:$W$150) -> 0 | G33: =E33-D33 -> 0 | H33: =IF(C33<>"",0,"") -> 0 | I33: =IF(AND(D33="0",E33="0"),"SI",IF(COUNTIF(Ajustes!$S$3:$S$150,B33),"SI",IF(AND(D33=0,E33=0,NOT(ISBLANK(D33)),NOT(ISBLANK(E33))),"SI",""))) -> SI
A34: A | B34: UNILEVER DE ARGENTINA S.A. | C34: 45941 | D34: 0 | E34: 0 | F34: =SUMIF(Ajustes!$S$3:$S$150,Varios!B34,Ajustes!$U$3:$U$150)+SUMIF(Ajustes!$S$3:$S$150,Varios!B34,Ajustes!W$3:$W$150) -> 0 | G34: =E34-D34 -> 0 | H34: =IF(C34<>"",0,"") -> 0 | I34: =IF(AND(D34="0",E34="0"),"SI",IF(COUNTIF(Ajustes!$S$3:$S$150,B34),"SI",IF(AND(D34=0,E34=0,NOT(ISBLANK(D34)),NOT(ISBLANK(E34))),"SI",""))) -> SI
A35: A | B35: VARIOS | F35: =SUMIF(Ajustes!$S$3:$S$150,Varios!B35,Ajustes!$U$3:$U$150)+SUMIF(Ajustes!$S$3:$S$150,Varios!B35,Ajustes!W$3:$W$150) -> 0 | G35: =E35-D35 -> 0 | H35: =IF(C35<>"",0,"") | I35: =IF(AND(D35="0",E35="0"),"SI",IF(COUNTIF(Ajustes!$S$3:$S$150,B35),"SI",IF(AND(D35=0,E35=0,NOT(ISBLANK(D35)),NOT(ISBLANK(E35))),"SI","")))
F36: =SUMIF(Ajustes!$S$3:$S$150,Varios!B36,Ajustes!$U$3:$U$150)+SUMIF(Ajustes!$S$3:$S$150,Varios!B36,Ajustes!W$3:$W$150) -> 0 | G36: =E36-D36 -> 0 | H36: =IF(C36<>"",0,"") | I36: =IF(AND(D36="0",E36="0"),"SI",IF(COUNTIF(Ajustes!$S$3:$S$150,B36),"SI",IF(AND(D36=0,E36=0,NOT(ISBLANK(D36)),NOT(ISBLANK(E36))),"SI","")))
F37: =SUMIF(Ajustes!$S$3:$S$150,Varios!B37,Ajustes!$U$3:$U$150)+SUMIF(Ajustes!$S$3:$S$150,Varios!B37,Ajustes!W$3:$W$150) -> 0 | G37: =E37-D37 -> 0 | H37: =IF(C37<>"",0,"") | I37: =IF(AND(D37="0",E37="0"),"SI",IF(COUNTIF(Ajustes!$S$3:$S$150,B37),"SI",IF(AND(D37=0,E37=0,NOT(ISBLANK(D37)),NOT(ISBLANK(E37))),"SI","")))
F38: =SUMIF(Ajustes!$S$3:$S$150,Varios!B38,Ajustes!$U$3:$U$150)+SUMIF(Ajustes!$S$3:$S$150,Varios!B38,Ajustes!W$3:$W$150) -> 0 | G38: =E38-D38 -> 0 | H38: =IF(C38<>"",0,"") | I38: =IF(AND(D38="0",E38="0"),"SI",IF(COUNTIF(Ajustes!$S$3:$S$150,B38),"SI",IF(AND(D38=0,E38=0,NOT(ISBLANK(D38)),NOT(ISBLANK(E38))),"SI","")))
F39: =SUMIF(Ajustes!$S$3:$S$150,Varios!B39,Ajustes!$U$3:$U$150)+SUMIF(Ajustes!$S$3:$S$150,Varios!B39,Ajustes!W$3:$W$150) -> 0 | G39: =E39-D39 -> 0 | H39: =IF(C39<>"",0,"") | I39: =IF(AND(D39="0",E39="0"),"SI",IF(COUNTIF(Ajustes!$S$3:$S$150,B39),"SI",IF(AND(D39=0,E39=0,NOT(ISBLANK(D39)),NOT(ISBLANK(E39))),"SI","")))
F40: =SUMIF(Ajustes!$S$3:$S$150,Varios!B40,Ajustes!$U$3:$U$150)+SUMIF(Ajustes!$S$3:$S$150,Varios!B40,Ajustes!W$3:$W$150) -> 0 | G40: =E40-D40 -> 0 | H40: =IF(C40<>"",0,"") | I40: =IF(AND(D40="0",E40="0"),"SI",IF(COUNTIF(Ajustes!$S$3:$S$150,B40),"SI",IF(AND(D40=0,E40=0,NOT(ISBLANK(D40)),NOT(ISBLANK(E40))),"SI","")))
F41: =SUMIF(Ajustes!$S$3:$S$150,Varios!B41,Ajustes!$U$3:$U$150)+SUMIF(Ajustes!$S$3:$S$150,Varios!B41,Ajustes!W$3:$W$150) -> 0 | G41: =E41-D41 -> 0 | H41: =IF(C41<>"",0,"") | I41: =IF(AND(D41="0",E41="0"),"SI",IF(COUNTIF(Ajustes!$S$3:$S$150,B41),"SI",IF(AND(D41=0,E41=0,NOT(ISBLANK(D41)),NOT(ISBLANK(E41))),"SI","")))
F42: =SUMIF(Ajustes!$S$3:$S$150,Varios!B42,Ajustes!$U$3:$U$150)+SUMIF(Ajustes!$S$3:$S$150,Varios!B42,Ajustes!W$3:$W$150) -> 0 | G42: =E42-D42 -> 0 | H42: =IF(C42<>"",0,"") | I42: =IF(AND(D42="0",E42="0"),"SI",IF(COUNTIF(Ajustes!$S$3:$S$150,B42),"SI",IF(AND(D42=0,E42=0,NOT(ISBLANK(D42)),NOT(ISBLANK(E42))),"SI","")))
F43: =SUMIF(Ajustes!$S$3:$S$150,Varios!B43,Ajustes!$U$3:$U$150)+SUMIF(Ajustes!$S$3:$S$150,Varios!B43,Ajustes!W$3:$W$150) -> 0 | G43: =E43-D43 -> 0 | H43: =IF(C43<>"",0,"") | I43: =IF(AND(D43="0",E43="0"),"SI",IF(COUNTIF(Ajustes!$S$3:$S$150,B43),"SI",IF(AND(D43=0,E43=0,NOT(ISBLANK(D43)),NOT(ISBLANK(E43))),"SI","")))
F44: =SUMIF(Ajustes!$S$3:$S$150,Varios!B44,Ajustes!$U$3:$U$150)+SUMIF(Ajustes!$S$3:$S$150,Varios!B44,Ajustes!W$3:$W$150) -> 0 | G44: =E44-D44 -> 0 | H44: =IF(C44<>"",0,"") | I44: =IF(AND(D44="0",E44="0"),"SI",IF(COUNTIF(Ajustes!$S$3:$S$150,B44),"SI",IF(AND(D44=0,E44=0,NOT(ISBLANK(D44)),NOT(ISBLANK(E44))),"SI","")))
F45: =SUMIF(Ajustes!$S$3:$S$150,Varios!B45,Ajustes!$U$3:$U$150)+SUMIF(Ajustes!$S$3:$S$150,Varios!B45,Ajustes!W$3:$W$150) -> 0 | G45: =E45-D45 -> 0 | H45: =IF(C45<>"",0,"") | I45: =IF(AND(D45="0",E45="0"),"SI",IF(COUNTIF(Ajustes!$S$3:$S$150,B45),"SI",IF(AND(D45=0,E45=0,NOT(ISBLANK(D45)),NOT(ISBLANK(E45))),"SI","")))
B46: =COUNTA(B10:B45) -> 26 | C46: =COUNTA(C10:C45) -> 20 | D46: =SUM(D10:D45) -> 2973 | E46: =SUM(E10:E45) -> 2464 | F46: =SUM(F10:F45) -> -1268813.1 | G46: =SUM(G7:G45) -> -509 | H46: =COUNTIF(H10:H45,0) -> 20 | I46: =COUNTIF(I10:I45,"Si")/26 -> 0.76923077

Sheet Ajustes
A1: Medicamentos | G1: Perfumería | M1: Accesorios | S1: Varios
A2: Laboratorio | B2: ID ajuste + | C2: Monto Ajuste + | D2: ID ajuste - | E2: Monto Ajuste - | G2: Laboratorio | H2: ID ajuste + | I2: Monto Ajuste + | J2: ID ajuste - | K2: Monto Ajuste - | M2: Laboratorio | N2: ID ajuste + | O2: Monto Ajuste + | P2: ID ajuste - | Q2: Monto Ajuste - | S2: Laboratorio | T2: ID ajuste + | U2: Monto Ajuste + | V2: ID ajuste - | W2: Monto Ajuste -
A3: LEPETIT | B3: 190003219 | C3: 79875 | D3: 190003218 | E3: -145970 | G3: COTY ARGENTINA S.A. | J3: 190003312 | K3: -396299.59 | M3: QUÍMICA ESTRELLA | P3: 190003302 | Q3: -19087.99 | S3: KRAFT FOODS | T3: 190003671 | U3: 80600.62 | V3: 190003672 | W3: -578728.25
A4: PANALAB | B4: 190003492 | C4: 358643.61 | D4: 190003491 | E4: -324957.03 | G4: SAINT JULIEN S.A. | M4: EXIMIA | N4: 190003448 | O4: 51000 | S4: COCA COLA / FEMSA | V4: 190003574 | W4: -45124.02
A5: CASSARÁ | B5: 190003247 | C5: 59620 | D5: 190003249 | E5: -217200 | G5: KUIDAR | M5: EXIMIA | N5: 190003447 | O5: 26700.08 | S5: ENERGIZER ARGENTINA S.A.
A6: SCOTT-CASSARÁ | D6: 190003400 | E6: -23650 | G6: COLGATE | M6: CEPAGE | S6: ELITE | V6: 190003603 | W6: -33399.95
A7: VENT 3 | G7: PUIG ARGENTINA S.A. | J7: 190003438 | K7: -37749.96 | M7: WERFEN MEDICAL | P7: 190003584 | Q7: -152646.77 | S7: PHARMAMERICAN S
A8: VANNIER - GRUNE | G8: NEW REVLON ARGENTINA S.A. | M8: PANTYMED SA | N8: 190003579 | O8: 4351 | S8: OMRON
A9: VANNIER | G9: LOREAL ARGENTINA S.A. | J9: 190003437 | K9: -23196 | M9: BODY CARE | P9: 190003580 | Q9: -27246.04 | S9: JOHNSON & JOHNS
A10: SAVANT GENERIC | G10: BEIERSDORF | M10: ROCHE DIABETES | P10: 190003581 | Q10: -73521 | S10: LABORATORIOS DIRAL SRL | V10: 190003747 | W10: -4369.3
A11: ROSSMORE PHARMA | G11: VICHY | H11: 190003430 | I11: 262374.69 | J11: 190003429 | K11: -119496.19 | M11: PIERRE FABRE OR | P11: 190003582 | Q11: -11738.95 | S11: FELFORT | V11: 190003748 | W11: -495205.92
A12: ROSPAW | G12: VICHY | H12: 190003428 | I12: 220693.38 | M12: STIAL S.A | P12: 190003583 | Q12: -20400.09 | S12: HOME 2000 S.A. | V12: 190003746 | W12: -107320.69
A13: VALUGE | B13: 190003384 | C13: 73100.25 | D13: 190003385 | E13: -68747.67 | G13: GLAXOSMITHKLINE | H13: 190003369 | I13: 107143.99 | J13: 190003368 | K13: -257126.11 | M13: SIDUS - LIFESCA | S13: INSBRUCK | T13: 190003744 | U13: 74472.56 | V13: 190003745 | W13: -159738.13
A14: NOVARTIS | G14: UNILEVER DE ARGENTINA S.A. | J14: 190003207 | K14: -108580.71 | M14: DEMA
A15: NEO-DERMOS | G15: UNILEVER | H15: 190003176 | I15: 53510.48 | J15: 190003175 | K15: -26426 | M15: ABBOTT DIABETES
A16: PHARMATRIX | G16: UNILEVER | H16: 190003187 | I16: 36591.14 | J16: 190003185 | K16: -42727.59 | M16: PHARMAMERICAN S
A17: RONTAG | G17: UNILEVER | J17: 190003192 | K17: -101816.4 | M17: PIERRE FABRE DE
A18: PÉREZ | G18: QUÍMICA ESTRELLA | M18: PROCER
A19: OMICRON | G19: PROCTER & GAMBL | H19: 190003294 | I19: 56649.13 | J19: 190003295 | K19: -96603.77 | M19: WERFEN MEDICAL | P19: 190003585 | Q19: -13200.26
A20: NATURAL LIFE | B20: 190003412 | C20: 101623.56 | D20: 190003413 | E20: -58073.37 | G20: NOSOTRAS | J20: 190003310 | K20: -64048.06 | M20: PROPATO | P20: 190003590 | Q20: -19432.09
A21: MSD ARGENTINA S | G21: CANNON PUNTANA S.A. | H21: 190003314 | I21: 58610.09 | J21: 190003313 | K21: -79780.16 | M21: PROPATO | P21: 190003591 | Q21: -7427.99
A22: LAGOS | G22: BASICARE | M22: SILFAB | P22: 190003588 | Q22: -7770.01
A23: LABORATORIO MER | G23: L´OREAL MAQUILLAJE | M23: SYRA S.A. | P23: 190003589 | Q23: -51078.3
A24: LABORATORIO ENA | G24: SIN CLASIFICAR | M24: SEISEME S.A. | P24: 190003604 | Q24: -18542.79
A25: LAB INTERNACION | G25: COPAHUE | J25: 190003484 | K25: -400000 | M25: PARAFARM | N25: 190003606 | O25: 31438.95 | P25: 190003607 | Q25: -126284.74
A26: JANSSEN-CILAG | B26: 190003414 | C26: 14610.69 | G26: AISICO S.R.L. | M26: MAVERICK
A27: francelab | D27: 190003415 | E27: -25496.69 | G27: AVENT | M27: LABORATORIOS GASANA S.R.L. | P27: 190003622 | Q27: -42589.8
A28: novoplos | B28: 190003409 | C28: 11950 | D28: 190003423 | E28: -41700 | G28: RECKITT BENCKIS | M28: FORMULAB
A29: eczane | B29: 190003421 | C29: 16561.05 | D29: 190003422 | E29: -4549.89 | G29: PIERRE FABRE DE | M29: SUFARMA | N29: 190003623 | O29: 142201.43 | P29: 190003624 | Q29: -201142.12
A30: FERRING | G30: LA ROCHE-POSAY | M30: PORTA HNOS S.A. | N30: 190003631 | O30: 98363.24 | P30: 190003632 | Q30: -10930.63
A31: RICHET | B31: 190003420 | C31: 382014.12 | G31: KIMBERLY CLARK ARGENTINA S.A. | M31: LABORATORIO GRA
A32: provefarma | D32: 190003419 | E32: -14990 | G32: GILLETTE | M32: LAB. AZUL | N32: 190003630 | O32: 2926.08
A33: SIDUS | D33: 190003497 | E33: -12429.64 | G33: ISDIN | M33: GRIMBERG
A34: SOUBEIRAN CHOBE | G34: SUNSTAR | M34: LISTEN S.A.C.I.Y M. | N34: 190003634 | O34: 22356.14 | P34: 190003633 | Q34: -87760.01
A35: SERVIER | G35: DISWALD | M35: ANDRÓMACO
A36: FORMULAB | B36: 190003424 | C36: 12000 | D36: 190003425 | E36: -47000 | G36: ISSUE | M36: BAGÓ
A37: EUROLAB | B37: 190003426 | C37: 25580 | G37: KIMBERLY CLARK ARGENTINA S.A. | M37: BEIERSDORF | N37: 190003640 | O37: 1990 | P37: 190003642 | Q37: -118590
A38: DR.MADAUS | D38: 190003427 | E38: -5490 | G38: COMODEX S.A. | M38: ELEA | N38: 190003639 | O38: 31162.57 | P38: 190003641 | Q38: -87060.27
A39: CETUS | G39: DCCSA | M39: CASASCO | N39: 190003752 | O39: 1121978.6 | P39: 190003765 | Q39: -627314.86
A40: CELNOVA ARGENTI | G40: JEANNE ARTHES PARIS
...
